<?xml version="1.0"?>
<robot name="mohan_robot"> 
    <link name="base_link">
        <visual>
            <geometry>
                 <box size="0.6 0.3 0.1"/>
            </geometry>
            <material name = "red">
                 <color rgba="1 0.0 0.0 1"/>
            </material>
        </visual>
        <collision>
            <geometry>
                <box size = "0.1 0.1 0.1"/>
                </geometry>
        </collision>
        <inertial>
            <mass value="1.0"/>
            <inertia ixx="0.015" ixy="0.0375" ixz="0.0375" iyy="0.0" iyz="0.0" izz="0.0"/>
        </inertial> 
    </link>
    
    <link name = "front_caster_of_wheel">
        <visual>
            <geometry>
                <box size = "0.1 0.1 0.1"/>
            </geometry>    
            <material name = "green">
                <color rgba="0.0 0.1 0.0 0.1"/>
            </material>
        </visual>
        <collision>
            <geometry>
                <box size = "0.1 0.1 0.1"/>
            </geometry>
         </collision>
        <inertial>
            <mass value="0.1"/>
            <inertia ixx="0.00083" ixy="0.00083" ixz="0.000167" iyy="0.0" iyz="0.0" izz="0.0"/>
        </inertial>
            
    </link>      
    <joint name="front_caster_of_wheel" type="continuous">
        <axis xyz="0.0 0.0 1"/>
        <parent link="base_link"/>
        <child link="front_caster_of_wheel"/>
        <origin xyz="0.3 0.0 0.0" rpy="0.0 0.0 0.0"/>        
    </joint>  

    <link name = "front_wheel">
        <visual>
            <geometry>
                <cylinder radius="0.035" length="0.05"/>
            </geometry>
            <material name = "black">
            </material>

        </visual>
        <collision>
            <geometry>
                <cylinder radius="0.035" length="0.05"/>
            </geometry>
        </collision>
        <inertial>
            <mass value="0.1"/>
            <inertia ixx="5.1458e-5" ixy="5.1458e-5" ixz="5.1458e-5" iyy="0.0" iyz="0.0" izz="0.0"/>
        </inertial>
    </link>
    
    <joint name = "front_wheel_joint" type = "continuous">
        <axis xyz="0.0 0.0 1"/>
        <parent link="front_caster_of_wheel"/>
        <child link="front_wheel"/>
        <origin xyz="0.05 0.0 -0.05" rpy="-1.5708 0.0 0.0" />
    </joint>   

    <link name = "right_wheel">
        <visual>
            <geometry>
                <cylinder radius="0.035" length="0.05"/>
            </geometry>
            <material name = "black">
                <color rgba="0.0 0.0 0.0 1"/>
            </material>
        </visual>
        <collision>
            <geometry>
                <cylinder radius="0.035" length="0.05"/>
            </geometry>
        </collision>
        <inertial>
            <mass value="0.1"/>
            <inertia ixx="5.1458e-5" ixy="5.1458e-5" ixz="5.1458e-5" iyy="0.0" iyz="0.0" izz="0.0"/>
        </inertial>    
    </link>


    <joint name="right_wheel_joint" type="continuous">
        <axis xyz="0.0 0.0 1"/>
        <parent link="base_link"/>
        <child link="right_wheel"/>
        <origin xyz="-0.2825 -0.125 -0.05" rpy = "-1.5708 0.0 0.0 " />
        
    </joint>     

    
    <link name = "left_wheel">
        <visual>
            <geometry>
                <cylinder radius="0.035" length="0.05"/>
            </geometry>
            <material name = "black">
                <color rgba="0.0 0.0 0.0 1"/>
            </material>
        </visual>
        <collision>
            <geometry>
                <cylinder radius="0.035" length="0.05"/>
            </geometry>    
        </collision>
        <inertial>
            <mass value="0.1"/>
            <inertia ixx="5.1458e-5" ixy="5.1458e-5" ixz="5.1458e-5" iyy="0.0" iyz="0.0" izz="0.0"/>
        </inertial>  
    </link>    

    <joint name="left_wheel_joint" type="continuous">
        <axis xyz="0.0 0.0 1"/>
        <parent link="base_link"/>
        <child link="left_wheel"/>
        <origin xyz="-0.2825 0.125 -0.05" rpy = "-1.5708 0.0 0.0 " />
        
    </joint>         

</robot>